<?xml version="1.0"?>

<robot name="robot">
  
  <!-- *************************************************** -->
  <!-- ******************** Kinematics ******************* -->
  <!-- *************************************************** -->
  <!-- Note the 'origin' tag in the fixed joints defines the shift and
       reorientation before the continuous joint rotates around the
       axis.  For shift distances see below. -->

  <link name="world"/>


  <joint name="connect-world-motor0base" type="fixed">
    <parent link="world"/>
    <child  link="motor0base"/>
    <origin xyz="0.25 0 0" rpy="0 0 0"/>
  </joint>
  <link name="motor0base"/>


  <joint name="Scara/0" type="continuous">
    <parent link="motor0base"/>
    <child  link="motor0output"/>
    <axis   xyz="0 0 1"/>
    <origin xyz="0 0 0" rpy="0 0 0.48918420473207647"/>
  </joint>
  <link name="motor0output"> </link>



  <joint name="connect-motor0output-motor1base" type="fixed">
    <parent link="motor0output"/>
    <child  link="motor1base"/>
    <origin xyz="0.5 0 0" rpy="0 3.1415926535 0"/>
  </joint>
  <link name="motor1base"/>


  <joint name="Scara/1" type="continuous">
    <parent link="motor1base"/>
    <child  link="motor1output"/>
    <axis   xyz="0 0 1"/>
    <origin xyz="0 0 0" rpy="0 0 0.2562432289123535"/>
  </joint>
  <link name="motor1output"> </link>



  <joint name="connect-motor1output-tip" type="fixed">
    <parent link="motor1output"/>
    <child  link="tip"/>
    <origin xyz="0 0.5 0" rpy="0 0 0"/>
  </joint>
  <link name="tip"/>


</robot>
