<?xml version="1.0"?>

<robot name="5dof">
  
  <!-- *************************************************** -->
  <!-- ******************** Kinematics ******************* -->
  <!-- *************************************************** -->
  <!-- Note the 'origin' tag in the fixed joints defines the shift and
       reorientation before the continuous joint rotates around the
       axis.  For shift distances see below. -->

  <link name="world"/>


  <joint name="connect-world-q0minus" type="fixed">
    <parent link="world"/>
    <child  link="q0minus"/>
    <origin xyz="0.32 -0.006 0" rpy="0 0 0"/>
  </joint>
  <link name="q0minus"/>


  <joint name="Picker/0" type="continuous">
    <parent link="q0minus"/>
    <child  link="q0plus"/>
    <axis   xyz="0 0 1"/>
  </joint>
  <link name="q0plus"/>


  <joint name="connect-q0plus-q1minus" type="fixed">
    <parent link="q0plus"/>
    <child  link="q1minus"/>
    <origin xyz="0 0 0.091" rpy="0 -1.5707963267949 0"/>
  </joint>
  <link name="q1minus"/>


  <joint name="Picker/1" type="continuous">
    <parent link="q1minus"/>
    <child  link="q1plus"/>
    <axis   xyz="0 0 1"/>
  </joint>
  <link name="q1plus"/>


  <joint name="connect-q1plus-q2minus" type="fixed">
    <parent link="q1plus"/>
    <child  link="q2minus"/>
    <origin xyz="0.283 0 0" rpy="0 0 0"/>
  </joint>
  <link name="q2minus"/>


  <joint name="Picker/2" type="continuous">
    <parent link="q2minus"/>
    <child  link="q2plus"/>
    <axis   xyz="0 0 1"/>
  </joint> 
  <link name="q2plus"/>


  <joint name="connect-q2plus-q3minus" type="fixed">
    <parent link="q2plus"/>
    <child  link="q3minus"/>
    <origin xyz="0.373 0 0" rpy="0 0 0"/>
  </joint>
  <link name="q3minus"/>


  <joint name="Picker/3" type="continuous">
    <parent link="q3minus"/>
    <child  link="q3plus"/>
    <axis   xyz="0 0 1"/>
  </joint> 
  <link name="q3plus"/>


  <joint name="connect-q3plus-tip" type="fixed">
    <parent link="q3plus"/>
    <child  link="tip"/>
    <origin xyz="0.1 0 0" rpy="0 1.5707963267949 0"/>
  </joint>
  <link name="tip"/>


</robot>
