<?xml version="1.0"?>

<robot name="robot">
  
  <!-- *************************************************** -->
  <!-- ******************** Kinematics ******************* -->
  <!-- *************************************************** -->
  <!-- Note the 'origin' tag in the fixed joints defines the shift and
       reorientation before the continuous joint rotates around the
       axis.  For shift distances see below. -->

  <link name="world"/>


  <link name="motor0base"/>
  <joint name="connect-world-motor0base" type="fixed">
    <parent link="world"/>
    <child  link="motor0base"/>
    <origin xyz="0.25 0 0" rpy="0 0 0"/>
  </joint>


  <link name="motor0output"/>
  <joint name="Chewbacca/q0" type="continuous">
    <parent link="motor0base"/>
    <child  link="motor0output"/>
    <axis   xyz="0 0 1"/>
  </joint>






  <link name="motor1base"/>
  <joint name="connect-motor0output-motor1base" type="fixed">
    <parent link="motor0output"/>
    <child  link="motor1base"/>
    <origin xyz="0 0 0.1" rpy="0 -1.5707963267949 0"/>
  </joint>


  <link name="motor1output"/>
  <joint name="Chewbacca/q1" type="continuous">
    <parent link="motor1base"/>
    <child  link="motor1output"/>
    <axis   xyz="0 0 1"/>
  </joint>


  <link name="motor2base"/>
  <joint name="connect-motor1output-motor2base" type="fixed">
    <parent link="motor1output"/>
    <child  link="motor2base"/>
    <origin xyz="0.4 0 0" rpy="0 0 0"/>
  </joint>

  <link name="motor2output"/>
  <joint name="Chewbacca/q2" type="continuous">
    <parent link="motor2base"/>
    <child  link="motor2output"/>
    <axis   xyz="0 0 1"/>
  </joint> 


  <link name="motor3base"/>
  <joint name="connect-motor2output-motor3base" type="fixed">
    <parent link="motor2output"/>
    <child  link="motor3base"/>
    <origin xyz="0.5 0 0" rpy="-1.5707963267949 0 0"/>
  </joint>

  <link name="motor3output"/>
  <joint name="Chewbacca/q3" type="continuous">
    <parent link="motor3base"/>
    <child  link="motor3output"/>
    <axis   xyz="0 0 1"/>
  </joint> 

  <link name="motor4base"/>
  <joint name="connect-motor3output-motor4base" type="fixed">
    <parent link="motor3output"/>
    <child  link="motor4base"/>
    <origin xyz="0 0 0.5" rpy="1.5707963267949 0 0"/>
  </joint>

  <link name="motor4output"/>
  <joint name="Chewbacca/q4" type="continuous">
    <parent link="motor4base"/>
    <child  link="motor4output"/>
    <axis   xyz="0 0 1"/>
  </joint> 


  <joint name="connect-motor4output-tip" type="fixed">
    <parent link="motor4output"/>
    <child  link="tip"/>
    <origin xyz="0 0.2 0" rpy="0 0 0"/>
  </joint>
  <link name="tip"/>


</robot>
